Workbook

Sheet SKU
A1: Campaign | B1: Link GMV MAX/ VSA | C1: Nama Produk | D1: Product ID | E1: Satuan/ Bundle | F1: Link TAP | G1: Commision
A2: Salsa Cosmetics | B2: VSA | C2: [SALSA x TNT] [BUNDLE SUPER HEMAT] SALSA Body B.L.E.A.C.H - Body Glow Serum Symphony | Body Serum Handbody Lotion | Body Lotion Mencerahkan | Body Care | Hand Body Lotion untuk Mencerahkan dan Melembabkan Kulit dengan 10+ Whitening Agent (Agen Pencerah) | D2: 1731683767804069499 | E2: Bundling | F2: https://affiliate-id.tokopedia.com/api/v1/share/AKSHh8Gb5ttm | G2: 0.09
A3: Salsa Cosmetics | B3: VSA | C3: [SALSA x TNT] SALSA Body B.L.E.A.C.H - Body Glow Serum Symphony | Hand Body Lotion untuk Mencerahkan dan Melembabkan Kulit dengan 10+ Whitening Agent (Agen Pencerah) | D3: 1732274522754877051 | E3: Satuan | F3: https://affiliate-id.tokopedia.com/api/v1/share/AKSHX12B2ZEc | G3: 0.09
A4: Salsa Cosmetics | B4: VSA | C4: [SALSA x TNT] SALSA Healthy Hair Serum - Vitamin Rambut Spray|Hair Vitamin|Perawatan Rambut Anti Rontok Ketombe Gatal Mengembang Lepek|Vitamin Rambut|Serum Rambut | Hair Tonic | Hair Tonic Vitamin | Vitamin Hair | D4: 1733603538440717947 | E4: Satuan | F4: https://affiliate-id.tokopedia.com/api/v1/share/AKSHX9h525me | G4: 0.09
A5: Salsa Cosmetics | B5: VSA | C5: [SALSA x TNT] SALSA Skincare Series - Perawatan Wajah Mencerahkan Glowing Berjerawat Samarkan Noda Hitam| Facial Wash Brightening & Low pH Sabun Cuci Muka|Acne Spot|Sunscreen|Krim Malam InstaGlow|Krim Pagi Siang Tone Up|Essence Serum | D5: 1733603981401818747 | E5: Bundling | F5: https://affiliate-id.tokopedia.com/api/v1/share/AKSHmVVN6KFl | G5: 0.1
A6: Salsa Cosmetics | B6: VSA | C6: [SALSA x TNT] Paket Sedekah Bebas Jerawat | Instaglow Cream | Acne Spot | Facial Wash Low pH | Skincare Routine | Perawatan Kulit | Hilangkan Jerawat | Facial Wash | Jerawat Solution | Harga Terjangkau | Acne Treatment | Sabun Cuci Muka | D6: 1734947448473618043 | E6: Bundling | F6: https://affiliate-id.tokopedia.com/api/v1/share/AKSHmZQfG93j | G6: 0.1
A7: Salsa Cosmetics | B7: VSA | C7: [SALSA x TNT] Paket Sedekah Glowing dan Cerah | Krim Malam Instaglow | Krim Siang Tone Up | Facial Wash Brightening | Sabun Cuci Muka | Wajah Glowing | Skincare Routine | Mencerahkan Kulit | Moisturizer | Brightening | Harga Terjangkau Perawatan | D7: 1734947544692786811 | E7: Bundling | F7: https://affiliate-id.tokopedia.com/api/v1/share/AKSHpEKODLxf | G7: 0.1
A8: Salsa Cosmetics | B8: VSA | C8: [SALSA x TNT] Paket Komplit Booster Glow Skincare | Krim Malam Krim Siang | Tone up Cream | Facial Wash | Acne Spot | Sunscreen | Serum Wajah | Skincare Routine | Menyamarkan Noda Hitam | Anti Jerawat | Mencerahkan Kulit | Hasil Maksimal | Tone Up Cream | D8: 1734947546425427579 | E8: Bundling | F8: https://affiliate-id.tokopedia.com/api/v1/share/AKSHigzlOIvs | G8: 0.1
A9: Salsa Cosmetics | B9: VSA | C9: [SALSA x TNT] Paket Komplit Glowing dan Cerah | Krim Malam Krim Siang | Brightening Essence | Tone Up Cream | Glowing | Skincare Routine | Mencerahkan Kulit | Hasil Maksimal | Daily Use | Gentle Formula Perawatan Kulit | Serum Wajah | D9: 1734947548571928187 | E9: Bundling | F9: https://affiliate-id.tokopedia.com/api/v1/share/AKSHpT5QeZtI | G9: 0.1
A10: Salsa Cosmetics | B10: VSA | C10: [SALSA x TNT] Paket Pemula Glowing dan Cerah | Instaglow Krim Malam | Tone Up Krim Siang | Facial Wash Brightening | Glowing | Perlindungan UV | Skincare Routine | Skin Brightening | Harga Terjangkau | Daily Use Perawatan Kulit | Sabun Cuci Muka | D10: 1734947596179244667 | E10: Bundling | F10: https://affiliate-id.tokopedia.com/api/v1/share/AKE5hv8jxRJr | G10: 0.1
A11: Salsa Cosmetics | B11: VSA | C11: [SALSA x TNT] Paket Pemula Bebas Jerawat | Instaglow Cream | Acne Spot | Krim Siang Tone Up | Anti Jerawat | Acne Treatment | Solusi Jerawat | Perlindungan UV | Daily Use | Harga Terjangkau Perawatan Kulit | Sun Blok | D11: 1734947596477236859 | E11: Bundling | F11: https://affiliate-id.tokopedia.com/api/v1/share/AKSHpZ5Ip3dH | G11: 0.1
A12: Salsa M&B | B12: VSA | C12: [SALSA BABY x TNT] SALSA BABY Fresh Oil Telon – Minyak Telon | Minyak Bayi | Minyak Bayi Anti Nyamuk | Menghangatkan | Newborn | D12: 1733607790132495849 | E12: Satuan | F12: https://affiliate-id.tokopedia.com/api/v1/share/AJePEe6jD3sW | G12: 0.1
A13: Salsa M&B | B13: VSA | C13: [SALSA BABY x TNT] SALSA BABY Sunscreen SPF30+ PA++++ – Sunscreen bayi | Tabir Surya Bayi | perlindungan sinar UV | D13: 1733607796563477993 | E13: Satuan | F13: https://affiliate-id.tokopedia.com/api/v1/share/AJePEgzrkRjs | G13: 0.1
... A46: Iswhite | B46: Organic (GMV MAX BRAND) | C46: [ EKSTRA HEMAT ] ISWHITE Ultimate Brightening Body Mask 200gr- Body Mask Masker Badan Pencerah Tubuh Glowing | D46: 1729607316247578238 | E46: Bundling | F46: https://affiliate-id.tokopedia.com/api/v1/share/AKLROhgkVOnH | G46: 0.05

Sheet DATABASE
A1: File | B1: Sheet | C1: Link Sheet
A2: Database | B2: Internal | C2: Database TNT

Sheet NO KONTRAK
A1: OMG Makeup | D1: OMG Skincare | G1: SKINMOLOGY | J1: QAHIRA | M1: WARDAH | P1: SALSA BABY | S1: SALSA COSMETIC | V1: DIOLY | Y1: ISWHITE | AB1: SYB | AE1: NAISDAY | AH1: MS GLOW BEAUTY
A2: Username | B2: No Surat | D2: Username | E2: No Surat | G2: Username | H2: No Surat | J2: Username | K2: No Surat | M2: Username | N2: No Surat | P2: Username | Q2: No Surat | S2: Username | T2: No Surat | V2: Username | W2: No Surat | Y2: Username | Z2: No Surat | AB2: Username | AC2: No Surat | AE2: Username | AF2: No Surat | AH2: Username | AI2: No Surat
A3: thya_pookie | B3: 001 | D3: shavirapuspitacitra | E3: 1 | G3: itscendi | H3: 1 | J3: talithazi_ | K3: 1 | M3: oinlubis_ | N3: 1 | P3: lisdapr | Q3: 1 | S3: thnlykai | T3: 001 | V3: moodtiaraaaaa | W3: 001 | Y3: gabolegalakya | Z3: 1 | AB3: zihanokta | AC3: 1 | AE3: zihanokta | AF3: 001 | AI3: 001
A4: mia07024 | B4: 002 | D4: ekbardiary | E4: 2 | G4: thya_pookie | H4: 2 | J4: ko.pepen | K4: 2 | M4: yourbesties77 | N4: 2 | P4: lidyafebriy | Q4: 2 | S4: ummashanum | T4: 002 | V4: thnlykai | W4: 002 | Y4: thnlykai | Z4: 2 | AB4: lilyisnotflowerrr | AC4: 2 | AF4: 002 | AI4: 002
A5: stuffbbydiy | B5: 003 | D5: nris9 | E5: 3 | G5: fitrianahisnainy | H5: 3 | J5: ekaretnowati | K5: 3 | M5: araanrml | N5: 3 | P5: ajtwinziee_ | Q5: 3 | S5: nris9 | T5: 003 | V5: thya_pookie | W5: 003 | Y5: euphoriatz | Z5: 3 | AB5: ndaahq | AC5: 3 | AF5: 003 | AI5: 003
A6: nris9 | B6: 004 | D6: azahrahf | E6: 4 | G6: ferenaceta | H6: 4 | J6: teungkuridhwan | K6: 4 | M6: thnlykai | N6: 4 | P6: Umiwahyuni04 | Q6: 4 | S6: ferenaceta | T6: 004 | V6: ummashanum | W6: 004 | Y6: zihanokta | Z6: 4 | AB6: ayuulestariii31 | AC6: 4 | AF6: 004 | AI6: 004
A7: gadisaries97 | B7: 005 | D7: arnilawati | E7: 5 | G7: itsmeevaniii | H7: 5 | J7: riskadiana22_ | K7: 5 | M7: thya_pookie | N7: 5 | P7: Momhiroki | Q7: 5 | S7: thya_pookie | T7: 005 | V7: ferenaceta | W7: 005 | Y7: pch992 | Z7: 5 | AC7: 5 | AF7: 005 | AI7: 005
A8: arranrml | B8: 006 | D8: mood.umrah | E8: 6 | G8: nris9 | H8: 6 | J8: nonazawa | K8: 6 | M8: moodtiaraaaaa | N8: 6 | P8: honeyhanyy | Q8: 6 | S8: gadisaries97 | T8: 006 | V8: nris9 | W8: 006 | Y8: itscendi | Z8: 6 | AC8: 6 | AF8: 006 | AI8: 006
A9: ummashanum | B9: 007 | D9: thya_pookie | E9: 7 | G9: gadisaries97 | H9: 7 | J9: mei_arifin180899 | K9: 7 | M9: syahvitridewi | N9: 7 | P9: andriani.26 | Q9: 7 | S9: mrsrepiew | T9: 007 | V9: lehabottoh | W9: 007 | Y9: ndaahq | Z9: 7 | AF9: 007 | AI9: 007
A10: itsmeevaniii | B10: 008 | D10: pinkskieslova | E10: 8 | G10: thnlykai | H10: 8 | J10: bunda.saba1 | K10: 8 | M10: intnwulnn_ | N10: 8 | P10: babyzaraa_ | Q10: 8 | S10: moodtiaraaaaa | T10: 008 | V10: elzahiraa25 | W10: 008 | Y10: andyraka | Z10: 8 | AF10: 008 | AI10: 008
A11: itscendi | B11: 009 | D11: ferenaceta | E11: 9 | G11: ekbardiary | H11: 9 | J11: omaliherbal | K11: 9 | P11: Biinbiinstore | Q11: 9 | S11: sabinaaccura | T11: 009 | V11: sygkmu__3 | W11: 009 | Y11: si.imel | Z11: 9 | AF11: 009 | AI11: 009
A12: thnlykai | B12: 010 | D12: mutiaraaarv | E12: 10 | G12: nonazawa | H12: 10 | J12: nadiapurba53 | K12: 10 | P12: mamanyacila28 | Q12: 10 | S12: fitrianahisnainy | T12: 010 | V12: rika_yusnia | W12: 010 | Y12: ayuulestariii31 | Z12: 10 | AF12: 010 | AI12: 010
A13: fitrianahisnainy | B13: 011 | D13: _cipo07 | E13: 11 | G13: mrsrepiew | H13: 11 | J13: shatikah04 | K13: 11 | P13: baby.cyrania | Q13: 11 | S13: ekbardiary | T13: 013 | V13: inii.dyan | W13: 011 | AF13: 011 | AI13: 011
A14: bbydreamer | B14: 012 | D14: nonazawa | E14: 12 | J14: gentongku | K14: 12 | P14: callin_lim | Q14: 12 | S14: hayndep | T14: 014 | V14: anayeppeo77 | W14: 012 | AF14: 012 | AI14: 012
A15: mrsrepiew | B15: 013 | D15: azzazhr21 | E15: 13 | J15: maiaannisa | K15: 13 | S15: muhannah.fitria | T15: 015 | V15: itsme_enjesyn | W15: 013 | AF15: 013 | AI15: 013
A16: moodtiaraaaaa | B16: 014 | D16: thnlykai | E16: 14 | J16: aaaratted | K16: 14 | S16: tesazakia | T16: 016 | V16: aghania02 | W16: 014 | AF16: 014 | AI16: 014
A17: anindalsp_ | B17: 015 | D17: moodtiaraaaaa | E17: 15 | J17: lisna_tanjung | K17: 15 | S17: gabolehgalakya | T17: 017 | V17: reviewofbeauty | W17: 015 | AF17: 015 | AI17: 015
A18: ncaaaaaaa24_ | B18: 016 | D18: itscendi | E18: 16 | J18: duonisaa_ | K18: 16 | S18: intnwulnn_ | T18: 018 | V18: review.erna27 | W18: 016 | AF18: 016 | AI18: 016
A19: dratcyunnn | B19: 017 | D19: letssgloow | E19: 17 | J19: 92herlina | K19: 17 | S19: itscendi | T19: 019 | V19: meirayu2 | W19: 017 | AF19: 017 | AI19: 017
A20: si.imel | B20: 018 | D20: iwantu2ndmoon | E20: 18 | J20: nam.bar3 | K20: 18 | S20: afrillamuthiia | T20: 020 | V20: haymawardah12 | W20: 018 | AF20: 018 | AI20: 018
A21: choconad22 | B21: 019 | D21: rannmovv | E21: 19 | J21: nul.minul | K21: 19 | S21: inidinddaaa | T21: 021 | V21: raninuraeni143 | W21: 019 | AF21: 019 | AI21: 019
A22: ekbardiary | B22: 020 | D22: muhannah.fitris | E22: 20 | J22: zoom_experimental | K22: 20 | S22: ndaahq | T22: 022 | V22: isnainimaria2 | W22: 020 | AF22: 020 | AI22: 020
A23: egaarmwt | B23: 021 | D23: gabolegalakya | E23: 21 | J23: dokterpuja | K23: 21 | S23: hnrusdiana | T23: 023 | V23: cherry_review21 | W23: 021
A24: shavirapuspitacitra | B24: 022 | D24: pch992 | E24: 22 | J24: meihrdnt_ | K24: 22
A25: tika_dewi027 | B25: 023 | D25: arsykhumairah27 | E25: 23 | J25: sii.lifa | K25: 23
A26: depeyyyy | B26: 024 | J26: semestakamuu | K26: 24
A27: syahvitridewi | B27: 025 | J27: daily_rosse | K27: 25
A28: sabinaaccura | B28: 026
A29: hananugroho_ | B29: 027
A30: dindaaprd_ | B30: 028
A31: lilyisnotflowerrr | B31: 029
A32: zihanokta | B32: 030

Sheet TEMPLATE QONTAK
A1: Campaign | B1: Template | C1: Status Qontak

Sheet Maindata
A1: Sales Campaign
A2: No | B2: Campaign | C2: 14 Days Preparation | D2: Start Date | E2: End Date | F2: ! Countdown ! | G2: Budget Creator (Sisa) | H2: Budget ADS (Sisa) | I2: Target | J2: Achievement | K2: Percentage (%) | L2: VSA/ GMV MAX | M2: PIC | N2: Assist | O2: Link External | P2: File Concept
A3: 1 | B3: OMG Skincare | C3: 05 - 25 Januari | D3: 26 Januari 2026 | E3: 46138 | F3: =INT(E3-NOW()) & " days " -> -45 days | G3: =sum('OMG SKINCARE'!J10) -> 990000 | H3: =sum('OMG SKINCARE'!L10) -> 3000000 | I3: =SUM('Daily Performance'!A5) -> 1000000000 | J3: =SUM('Daily Performance'!C2:C3) -> 7.7079358e+08 | K3: =IFERROR(J3/I3,"N/A") -> 0.77079358 | L3: TRUE | M3: Tiara | N3: Wahyu | O3: OMG Skincare | P3: Konsep OMG Skincare
A4: 2 | B4: OMG Makeup | C4: 05 - 25 Januari | D4: 26 Januari 2026 | E4: 46138 | F4: =INT(E4-NOW()) & " days " -> -45 days | G4: =sum('OMG MAKEUP'!I10) -> 8575000 | H4: =sum('OMG MAKEUP'!K7) -> 25800000 | I4: =SUM('Daily Performance'!A15) -> 2500000000 | J4: =SUM('Daily Performance'!C12:C13) -> 673280168 | K4: =IFERROR(J4/I4,"N/A") -> 0.26931207 | L4: TRUE | M4: April | N4: Maria | O4: OMG Makeup | P4: Konsep OMG Makeup
A5: 3 | B5: Qahira | C5: 29 Januari - 18 Februari | D5: 18 Februari 2026 | E5: 46160 | F5: =INT(E5-NOW()) & " days " -> -23 days | G5: =sum(QAHIRA!K10) -> 5740000 | H5: =sum(QAHIRA!M10) -> 12760000 | I5: =SUM('Daily Performance'!A25) -> 500000000 | J5: =SUM('Daily Performance'!C22:C23) -> 98661175 | K5: =IFERROR(J5/I5,"N/A") -> 0.19732235 | L5: TRUE | M5: April | N5: Tiara | O5: Qahira | P5: Konsep Qahira
A6: 4 | B6: Salsa Cosmetics | C6: 05 - 22 Januari | D6: 22 Februari 2026 | E6: 46164 | F6: =INT(E6-NOW()) & " days " -> -19 days | G6: =sum('SALSA COSME'!I7) -> 4792000 | H6: =sum('SALSA COSME'!K7) -> 15000000 | I6: =SUM('Daily Performance'!A61) -> 750000000 | J6: =SUM('Daily Performance'!C58:C59) -> 234339337 | K6: =IFERROR(J6/I6,"N/A") -> 0.31245245 | L6: TRUE | M6: April | N6: Maria | O6: Salsa Cosmetics | P6: Konsep Salsa Cosmetics
A7: 5 | B7: Salsa Mom & Baby | C7: 05 - 22 Januari | D7: 22 Februari 2026 | E7: 46164 | F7: =INT(E7-NOW()) & " days " -> -19 days | G7: =sum('SALSA M&B'!I10) -> 10000000 | H7: =sum('SALSA M&B'!K10) -> 2000000 | I7: =SUM('Daily Performance'!A71) -> 200000000 | J7: =SUM('Daily Performance'!C68:C69) -> 65050469 | K7: =IFERROR(J7/I7,"N/A") -> 0.32525234 | L7: TRUE | M7: Marini | O7: Salsa M&B | P7: Konsep Salsa M&B
A8: 6 | B8: Wardah | C8: 12 - 26 Januari | D8: 02 Maret 2026 | E8: 46175 | F8: =INT(E8-NOW()) & " days " -> -8 days | G8: =sum(WARDAH!I10) -> 5100000 | H8: =sum(WARDAH!K10) -> 8000000 | I8: =SUM('Daily Performance'!A51) -> 150000000 | J8: =SUM('Daily Performance'!C48:C49) -> 13204326 | K8: =IFERROR(J8/I8,"N/A") -> 0.08802884 | L8: FALSE | M8: Marini | O8: Wardah | P8: Konsep Wardah
A9: 7 | B9: ISWHITE | C9: 06 - 20 April | D9: 46136 | E9: 46227 | F9: =INT(E9-NOW()) & " days " -> 44 days | G9: =sum(ISWHITE!J10) -> 10972500 | H9: =sum(ISWHITE!L10) -> 13000000 | I9: =SUM('Daily Performance'!A89) -> 600000000 | J9: =SUM('Daily Performance'!C86:C87) -> 6599755 | K9: =IFERROR(J9/I9,"N/A") -> 0.010999592 | L9: TRUE | M9: Tiara | N9: April | O9: ISWHITE | P9: Konsep Iswhite
A10: 8 | B10: NAISDAY | C10: 08 - 22 April | D10: 46136 | E10: 46227 | F10: =INT(E10-NOW()) & " days " -> 44 days | G10: =sum(NAISDAY!J10) -> 18200000 | H10: =sum(NAISDAY!L10) -> 17000000 | I10: =SUM('Daily Performance'!A89) -> 600000000 | J10: =SUM('Daily Performance'!C96:C97) -> 9890704 | K10: =IFERROR(J10/I10,"N/A") -> 0.016484507 | L10: TRUE | M10: Maria | O10: NAISDAY | P10: Konsep Naisday
A11: 9 | B11: SYB | C11: 21 April - 5 Mei | D11: 46148 | E11: 46240 | F11: =INT(E11-NOW()) & " days " -> 57 days | G11: =sum(SYB!J10) -> 38750000 | H11: =sum(SYB!L10) -> 32000000 | I11: =SUM('Daily Performance'!A109) -> 1500000000 | J11: =SUM('Daily Performance'!C106:C107) -> 17329022 | K11: =IFERROR(J11/I11,"N/A") -> 0.011552681 | L11: TRUE | M11: Tiara | O11: SYB | P11: Konsep SYB
A12: 10 | B12: Ms Glow Beauty | C12: 20 Mei - 2 Juni | D12: 3 Juni 2026 | E12: 46268 | F12: =INT(E12-NOW()) & " days " -> 85 days | G12: =sum(MSGLOWBEAUTY!J10) -> 112000000 | H12: =sum(MSGLOWBEAUTY!L10) -> 200000000 | I12: =SUM('Daily Performance'!A127) -> 4000000000 | J12: =SUM('Daily Performance'!C124:C125) -> 0 | K12: =IFERROR(J12/I12,"N/A") -> 0 | L12: FALSE | M12: Maria | O12: MSGLOWBEAUTY | P12: Konsep MSGlowBeauty
A13: 11 | B13: Ms Glow for Men | C13: 20 Mei - 2 Juni | D13: 6 Juni 2026 | E13: 46301 | F13: =INT(E13-NOW()) & " days " -> 118 days | G13: =sum(MSGLOWFORMEN!J10) -> 84000000 | H13: =sum(MSGLOWFORMEN!L10) -> 100000000 | I13: =SUM('Daily Performance'!A137) -> 1200000000 | J13: =SUM('Daily Performance'!C134:C135) -> 0 | K13: =IFERROR(J13/I13,"N/A") -> 0 | L13: FALSE | M13: Dafa | O13: MSGLOWFORMEN | P13: Konsep MSGlowMen
A15: Awareness Campaign
A16: No | B16: Campaign | C16: 14 Days Preparation | D16: Start Date | E16: End Date | G16: Budget Creator (Sisa) | H16: Budget Ads (Sisa) | I16: Target Creator | J16: Target Video | K16: Percentage (%) | L16: Achievement Creator | M16: Achievement Video | N16: Achievement Views | O16: PIC | P16: Assist | Q16: Link External | R16: File Concept
A17: 1 | B17: Kimme | C17: 21 Januari - 3 Februari | D17: 11 Februari 2026 | E17: 46173 | F17: =INT(E17-NOW()) & " days " -> -10 days | G17: =sum(KIMME!I10) -> 52915000 | I17: =SUM('Daily Performance'!B34) -> 3750 | J17: =SUM('Daily Performance'!B35) -> 15000 | K17: =IFERROR(M17/J17,"N/A") -> 0.55486667 | L17: =sum('Daily Performance'!C32) -> 2840 | M17: =sum('Daily Performance'!C33) -> 8323 | N17: 0 | O17: Wahyu | P17: Natali, April, Selfi | Q17: Kimme | R17: Konsep Kimme
A18: 2 | B18: Skinmology | C18: 23 - 31 Januari | D18: 1 Februari 2026 | E18: 01 Maret 2026 | G18: =sum(SKINMOLOGY!I10) -> 1197500 | I18: =SUM('Daily Performance'!B42) -> 70 | J18: =SUM('Daily Performance'!B43) -> 140 | K18: 0 | L18: =sum('Daily Performance'!C40) -> 70 | M18: =sum('Daily Performance'!C41) -> 140 | N18: 0 | O18: Maria | P18: Tiara | Q18: SKINMOLOGY X TNT | R18: Konsep Skinmology
A19: 2 | B19: Dioly | C19: 18 - 3 Maret | D19: 4 Maret 2026 | E19: 46153 | F19: =INT(E19-NOW()) & " days " -> -30 days | G19: =sum(DIOLY!I10) -> 5900000 | I19: 250 | J19: 500 | K19: =IFERROR(M19/J19,"N/A") -> 0.278 | L19: =sum('Daily Performance'!C78) -> 106 | M19: =sum('Daily Performance'!C79) -> 139 | O19: Maria | Q19: DIOLY X TNT | R19: Konsep Dioly
A20: 3 | B20: PWS | C20: 14-30 April 2026 | D20: 46149 | E20: 46241 | F20: =INT(E20-NOW()) & " days " -> 58 days | G20: 65.000.000 | I20: 3000 | J20: 10000 | K20: =IFERROR(M20/J20,"N/A") -> 0.1254 | L20: 1124 | M20: 1254 | O20: Marini | P20: Wahyu | Q20: PWS X TNT | R20: Konsep PWS

Sheet Daily Performance
A1: Campaign OMG Skincare | C1: Grand Total | D1: January | E1: Februari | F1: Maret | G1: April | H1: Mei | I1: 46174 | J1: 46175 | K1: 46176 | L1: 46177 | M1: 46178 | N1: 46179 | O1: 46180 | P1: 46181 | Q1: 46182 | R1: 46183 | S1: 46184 | T1: 46185 | U1: 46186 | V1: 46187 | W1: 46188 | X1: 46189 | Y1: 46190 | Z1: 46191 | AA1: 46192 | AB1: 46193 | AC1: 46194 | AD1: 46195 | AE1: 46196 | AF1: 46197 | AG1: 46198 | AH1: 46199 | AI1: 46200 | AJ1: 46201 | AK1: 46202 | AL1: 46203
A2: OMG Skincare | B2: Order Organic | C2: =SUM(D2:AJ2) -> 29541876 | D2: =SUMIFS(RAW_organic!$V:$V, RAW_organic!$A:$A, $B5, RAW_organic!$K:$K, "OMG") -> 0 | E2: 1005766 | F2: 1671154 | G2: 8839852 | H2: 13256495 | I2: 509530 | J2: 578493 | K2: 874972 | L2: 477172 | M2: 553977 | N2: 820671 | O2: 474121 | P2: 379211 | Q2: 100462
B3: VSA | C3: =SUM(D3:AI3) -> 7.412517e+08 | D3: 0 | E3: 0 | F3: 2.7199923e+08 | G3: 61762437 | H3: 264617351 | I3: 0 | J3: 120181700 | K3: 0 | L3: 0 | M3: 0 | N3: 0 | O3: 0 | P3: 22690985
A4: Total Target | B4: Percentage | C4: =SUM(D4:AI4) -> 0.77079358 | D4: =sum(D2:D3)/$A$5 -> 0 | E4: =sum(E2:E3)/$A$5 -> 0.001005766 | F4: =sum(F2:F3)/$A$5 -> 0.27367038 | G4: =sum(G2:G3)/$A$5 -> 0.070602289 | H4: =sum(H2:H3)/$A$5 -> 0.27787385 | I4: =sum(I2:I3)/$A$5 -> 0.00050953 | J4: =sum(J2:J3)/$A$5 -> 0.12076019 | K4: =sum(K2:K3)/$A$5 -> 0.000874972 | ... AL4: =sum(AL2:AL3)/$A$5 -> 0
A5: 1000000000 | B5: Total Video | C5: =sum(D5:AJ5) -> 251 | D5: 10 | E5: 72 | F5: 65 | G5: 49 | H5: 45 | I5: 1 | J5: 2 | K5: 1 | L5: 1 | M5: 1 | N5: 1 | O5: 1 | P5: 2
A6: Target Harian | B6: Total Live | C6: =sum(D6:AH6) -> 22 | E6: 9 | F6: 5 | G6: 8
A7: =(A5-(C2 + C3))/30 -> 7640214 | B7: Total Live Exclusive | C7: =sum(D7:U7) -> 0
B8: Target GMV/Hari | H8: =(A5-(C2 + C3))/30 -> 7640214 | I8: Rp21,835,025 | J8: Rp21,835,025 | K8: Rp21,835,025 | L8: Rp21,835,025 | M8: Rp21,835,025 | N8: Rp21,835,025 | O8: Rp21,835,025 | P8: Rp21,835,025 | Q8: Rp21,835,025 | R8: Rp21,835,025 | S8: Rp21,835,025 | T8: Rp21,835,025 | U8: Rp21,835,025 | V8: Rp21,835,025 | W8: Rp21,835,025 | X8: Rp21,835,025 | Y8: Rp21,835,025 | Z8: Rp21,835,025 | AA8: Rp21,835,025 | AB8: Rp21,835,025 | AC8: Rp21,835,025 | AD8: Rp21,835,025 | AE8: Rp21,835,025 | AF8: Rp21,835,025 | AG8: Rp21,835,025
B9: Target %/Hari | H9: 2,18% | I9: 2,18% | J9: 2,18% | K9: 2,18% | L9: 2,18% | M9: 2,18% | N9: 2,18% | O9: 2,18% | P9: 2,18% | Q9: 2,18% | R9: 2,18% | S9: 2,18% | T9: 2,18% | U9: 2,18% | V9: 2,18% | W9: 2,18% | X9: 2,18% | Y9: 2,18% | Z9: 2,18% | AA9: 2,18% | AB9: 2,18% | AC9: 2,18% | AD9: 2,18% | AE9: 2,18% | AF9: 2,18% | AG9: 2,18%
A10: End Date: 26 April 2026 | AG10: \
A11: Campaign OMG Make Up | C11: Grand Total | D11: January | E11: Februari | F11: Maret | G11: April | H11: Mei | I11: 46174 | J11: 46175 | K11: 46176 | L11: 46177 | M11: 46178 | N11: 46179 | O11: 46180 | P11: 46181 | Q11: 46182 | R11: 46183 | S11: 46184 | T11: 46185 | U11: 46186 | V11: 46187 | W11: 46188 | X11: 46189 | Y11: 46190 | Z11: 46191 | AA11: 46192 | AB11: 46193 | AC11: 46194 | AD11: 46195 | AE11: 46196 | AF11: 46197 | AG11: 46198 | AH11: 46199 | AI11: 46200 | AJ11: 46201 | AK11: 46202 | AL11: 46203
A12: OMG Makeup | B12: Order Organic | C12: =SUM(D12:AI12) -> 40422633 | D12: =SUMIFS(RAW_organic!$V:$V, RAW_organic!$A:$A, $B5, RAW_organic!$K:$K, "OMG Makeup") -> 0 | E12: 1067696 | F12: 3947061 | G12: 1865681 | H12: 21568927 | I12: 757630 | J12: 1456587 | K12: 1137163 | L12: 1496548 | M12: 1538336 | N12: 2472342 | O12: 1615211 | P12: 1233834 | Q12: 265617
B13: VSA | C13: =SUM(D13:AI13) -> 632857535 | D13: 0 | E13: 0 | F13: =305116678 -> 305116678 | G13: 125748724 | H13: 119689816 | J13: 59981110 | P13: 22321207
A14: Total Target | B14: Percentage | C14: =SUM(D14:AJ14) -> 0.26931207 | D14: =(D12+D13)/2500000000 -> 0 | E14: =(E12+E13)/2500000000 -> 0.0004270784 | F14: =(F12+F13)/2500000000 -> 0.1236255 | G14: =(G12+G13)/2500000000 -> 0.051045762 | H14: =(H12+H13)/2500000000 -> 0.056503497 | I14: =(I12+I13)/2500000000 -> 0.000303052 | J14: =(J12+J13)/2500000000 -> 0.024575079 | K14: =(K12+K13)/2500000000 -> 0.0004548652 | ... AL14: =(AL12+AL13)/2500000000 -> 0
A15: 2500000000 | B15: Total Video | C15: =sum(D15:AH15) -> 264 | D15: 15 | E15: 80 | F15: 42 | G15: 60 | H15: 58 | J15: 3 | K15: 3 | L15: 3
A16: Target Harian | B16: Total Live | C16: =sum(D16:AH16) -> 0
A17: =(A15-(C12 + C13))/14 -> 130479988 | B17: Total Live Exclusive | C17: =sum(D17:U17) -> 0
B18: Target GMV/Hari | H18: 72078015 | I18: 72078015 | J18: 72078015 | K18: 72078015 | L18: 72078015 | M18: 72078015 | N18: 72078015 | O18: 72078015 | P18: 72078015 | Q18: 72078015 | R18: 72078015 | S18: 72078015 | T18: 72078015 | U18: 72078015 | V18: 72078015 | W18: 72078015 | X18: 72078015 | Y18: 72078015 | Z18: 72078015 | AA18: 72078015 | AB18: 72078015 | AC18: 72078015 | AD18: 72078015 | AE18: 72078015 | AF18: 72078015 | AG18: 72078015
B19: Target %/Hari | H19: 2,88% | I19: 2,88% | J19: 2,88% | K19: 2,88% | L19: 2,88% | M19: 2,88% | N19: 2,88% | O19: 2,88% | P19: 2,88% | Q19: 2,88% | R19: 2,88% | S19: 2,88% | T19: 2,88% | U19: 2,88% | V19: 2,88% | W19: 2,88% | X19: 2,88% | Y19: 2,88% | Z19: 2,88% | AA19: 2,88% | AB19: 2,88% | AC19: 2,88% | AD19: 2,88% | AE19: 2,88% | AF19: 2,88% | AG19: 2,88%
A20: End Date: 26 April 2026 | AG20: \
A21: Campaign Qahira | C21: Grand Total | D21: Februari | E21: Maret | F21: April | G21: Mei | H21: 46174 | I21: 46175 | J21: 46176 | K21: 46177 | L21: 46178 | M21: 46179 | N21: 46180 | O21: 46181 | P21: 46182 | Q21: 46183 | R21: 46184 | S21: 46185 | T21: 46186 | U21: 46187 | V21: 46188 | W21: 46189 | X21: 46190 | Y21: 46191 | Z21: 46192 | AA21: 46193 | AB21: 46194 | AC21: 46195 | AD21: 46196 | AE21: 46197 | AF21: 46198 | AG21: 46199 | AH21: 46200 | AI21: 46201 | AJ21: 46202 | AK21: 46203
A22: Qahira | B22: Order Organic | C22: =SUM(D22:AI22) -> 36565797 | D22: 423975 | E22: 5791848 | F22: 13251415 | G22: 12904810 | H22: 538369 | I22: 1116363 | J22: 651104 | K22: 369455 | L22: 485397 | M22: 286183 | N22: 653742 | O22: 93136
B23: VSA | C23: =SUM(D23:AI23) -> 62095378 | D23: 0 | E23: 20603055 | F23: 17103524 | G23: 18772309 | I23: 4681418.2 | O23: 935071.44
A24: Total Target | B24: Percentage | C24: =SUM(D24:AI24) -> 0.19732235 | D24: =sum(D22:D23)/$A$25 -> 0.00084795 | E24: =sum(E22:E23)/$A$25 -> 0.052789806 | F24: =sum(F22:F23)/$A$25 -> 0.060709878 | G24: =sum(G22:G23)/$A$25 -> 0.063354238 | H24: =sum(H22:H23)/$A$25 -> 0.001076738 | I24: =sum(I22:I23)/$A$25 -> 0.011595562 | J24: =sum(J22:J23)/$A$25 -> 0.001302208 | K24: =sum(K22:K23)/$A$25 -> 0.00073891 | ... AK24: =sum(AK22:AK23)/$A$25 -> 0
A25: 500000000 | B25: Total Video | C25: =sum(D25:AI25) -> 279 | D25: 59 | E25: 80 | F25: 80 | G25: 50 | I25: 3 | J25: 3 | K25: 4
A26: Target Harian | B26: Total Live | C26: =sum(D26:AH26) -> 2 | E26: 2
A27: =(A25-(C22 + C23))/80 -> 5016735.3 | B27: Total Live Exclusive | C27: =sum(D27:AI27) -> 0
B28: Target GMV/Hari | G28: 26059775 | H28: 26059775 | I28: 26059775 | J28: 26059775 | K28: 26059775 | L28: 26059775 | M28: 26059775 | N28: 26059775 | O28: 26059775 | P28: 26059775 | Q28: 26059775 | R28: 26059775 | S28: 26059775 | T28: 26059775 | U28: 26059775 | V28: 26059775 | W28: 26059775 | X28: 26059775
B29: Target %/Hari | H29: 5,21% | I29: 5,21% | J29: 5,21% | K29: 5,21% | L29: 5,21% | M29: 5,21% | N29: 5,21% | O29: 5,21% | P29: 5,21% | Q29: 5,21% | R29: 5,21% | S29: 5,21% | T29: 5,21% | U29: 5,21% | V29: 5,21% | W29: 5,21% | X29: 5,21%
A30: End Date: 18 Mei 2026 | AG30: \
A31: Campaign Kime | C31: Grand Total | D31: Januari | E31: Februari | F31: Maret | G31: April | H31: Mei | I31: 46174 | J31: 46175 | K31: 46176 | L31: 46177 | M31: 46178 | N31: 46179 | O31: 46180 | P31: 46181 | Q31: 46182 | R31: 46183 | S31: 46184 | T31: 46185 | U31: 46186 | V31: 46187 | W31: 46188 | X31: 46189 | Y31: 46190 | Z31: 46191 | AA31: 46192 | AB31: 46193 | AC31: 46194 | AD31: 46195 | AE31: 46196 | AF31: 46197 | AG31: 46198 | AH31: 46199 | AI31: 46200 | AJ31: 46201 | AK31: 46202 | AL31: 46203
A32: Kimme | B32: Creator | C32: =SUM(D32:AL32) -> 2840 | D32: 171 | E32: 281 | F32: 619 | G32: 944 | H32: 459 | I32: 0 | J32: 66 | K32: 100 | L32: 119 | M32: 81
B33: Video | C33: =SUM(D33:AL33) -> 8323 | D33: 0 | E33: 290 | F33: 546 | G33: 1881 | H33: 4782 | I33: 0 | J33: 209 | K33: 150 | L33: 264 | M33: 201
A34: Target Creator | B34: 3750 | C34: =IFERROR(C32/B34,"N/A") -> 0.75733333 | D34: =IFERROR(D32/B34,"N/A") -> 0.0456 | E34: =IFERROR(E32/B34,"N/A") -> 0.074933333 | F34: =IFERROR(F32/B34,"N/A") -> 0.16506667 | G34: =IFERROR(G32/B34,"N/A") -> 0.25173333 | H34: =IFERROR(H32/B34,"N/A") -> 0.1224 | I34: =IFERROR(I32/B34,"N/A") -> 0 | J34: =IFERROR(J32/B34,"N/A") -> 0.0176 | K34: =IFERROR(K32/B34,"N/A") -> 0.026666667 | L34: =IFERROR(L32/B34,"N/A") -> 0.031733333 | M34: =IFERROR(M32/B34,"N/A") -> 0.0216 | N34: =IFERROR(N32/B34,"N/A") -> 0 | O34: =IFERROR(O32/B34,"N/A") -> 0 | P34: =IFERROR(P32/B34,"N/A") -> 0 | Q34: =IFERROR(Q32/B34,"N/A") -> 0 | R34: =IFERROR(R32/B34,"N/A") -> 0 | S34: =IFERROR(S32/B34,"N/A") -> 0 | T34: =IFERROR(T32/B34,"N/A") -> 0 | U34: =IFERROR(U32/B34,"N/A") -> 0 | V34: =IFERROR(V32/B34,"N/A") -> 0 | W34: =IFERROR(W32/B34,"N/A") -> 0 | X34: =IFERROR(X32/B34,"N/A") -> 0 | Y34: =IFERROR(Y32/B34,"N/A") -> 0 | Z34: =IFERROR(Z32/B34,"N/A") -> 0 | AA34: =IFERROR(AA32/B34,"N/A") -> 0 | AB34: =IFERROR(AB32/B34,"N/A") -> 0 | AC34: =IFERROR(AC32/B34,"N/A") -> 0 | AD34: =IFERROR(AD32/B34,"N/A") -> 0 | AE34: =IFERROR(AE32/B34,"N/A") -> 0 | AF34: =IFERROR(AF32/B34,"N/A") -> 0 | AG34: =IFERROR(AG32/B34,"N/A") -> 0 | AH34: =IFERROR(AH32/B34,"N/A") -> 0 | AI34: =IFERROR(AI32/B34,"N/A") -> 0 | AJ34: =IFERROR(AJ32/B34,"N/A") -> 0 | AK34: =IFERROR(AK32/C34,"N/A") -> 0 | AL34: =IFERROR(AL32/D34,"N/A") -> 0
A35: Target Video | B35: 15000 | C35: =IFERROR(C33/B35,"N/A") -> 0.55486667 | D35: =IFERROR(D33/B35,"N/A") -> 0 | E35: =IFERROR(E33/B35,"N/A") -> 0.019333333 | F35: =IFERROR(F33/B35,"N/A") -> 0.0364 | G35: =IFERROR(G33/B35,"N/A") -> 0.1254 | H35: =IFERROR(H33/B35,"N/A") -> 0.3188 | I35: =IFERROR(I33/B35,"N/A") -> 0 | J35: =IFERROR(J33/B35,"N/A") -> 0.013933333 | K35: =IFERROR(K33/B35,"N/A") -> 0.01 | L35: =IFERROR(L33/B35,"N/A") -> 0.0176 | M35: =IFERROR(M33/B35,"N/A") -> 0.0134 | N35: =IFERROR(N33/B35,"N/A") -> 0 | O35: =IFERROR(O33/B35,"N/A") -> 0 | P35: =IFERROR(P33/B35,"N/A") -> 0 | Q35: =IFERROR(Q33/B35,"N/A") -> 0 | R35: =IFERROR(R33/B35,"N/A") -> 0 | S35: =IFERROR(S33/B35,"N/A") -> 0 | T35: =IFERROR(T33/B35,"N/A") -> 0 | U35: =IFERROR(U33/B35,"N/A") -> 0 | V35: =IFERROR(V33/B35,"N/A") -> 0 | W35: =IFERROR(W33/B35,"N/A") -> 0 | X35: =IFERROR(X33/B35,"N/A") -> 0 | Y35: =IFERROR(Y33/B35,"N/A") -> 0 | Z35: =IFERROR(Z33/B35,"N/A") -> 0 | AA35: =IFERROR(AA33/B35,"N/A") -> 0 | AB35: =IFERROR(AB33/B35,"N/A") -> 0 | AC35: =IFERROR(AC33/B35,"N/A") -> 0 | AD35: =IFERROR(AD33/B35,"N/A") -> 0 | AE35: =IFERROR(AE33/B35,"N/A") -> 0 | AF35: =IFERROR(AF33/B35,"N/A") -> 0 | AG35: =IFERROR(AG33/B35,"N/A") -> 0 | AH35: =IFERROR(AH33/B35,"N/A") -> 0 | AI35: =IFERROR(AI33/B35,"N/A") -> 0 | AJ35: =IFERROR(AJ33/B35,"N/A") -> 0 | AK35: =IFERROR(AK33/C35,"N/A") -> 0 | AL35: =IFERROR(AL33/D35,"N/A") -> N/A
A36: Target Creator/ Hari | B36: =B34/50 -> 75 | K36: 258 | L36: 258 | M36: 258 | N36: 258 | O36: 258 | P36: 258 | Q36: 258
A37: Target Video/ Hari | B37: =B35/50 -> 300 | K37: 1.791 | L37: 1.791 | M37: 1.791 | N37: 1.791 | O37: 1.791 | P37: 1.791 | Q37: 1.791
A38: End Date: | AG38: \
A39: Campaign Skinmology | C39: Grand Total | D39: Februari | E39: Maret | F39: 46113 | G39: 46114 | H39: 46115 | I39: 46116 | J39: 46117 | K39: 46118 | L39: 46119 | M39: 46120 | N39: 46121 | O39: 46122 | P39: 46123 | Q39: 46124 | R39: 46125 | S39: 46126 | T39: 46127 | U39: 46128 | V39: 46129 | W39: 46130 | X39: 46131 | Y39: 46132 | Z39: 46133 | AA39: 46134 | AB39: 46135 | AC39: 46136 | AD39: 46137 | AE39: 46138 | AF39: 46139 | AG39: 46140 | AH39: 46141 | AI39: 46142
A40: Skinmology | B40: Creator | C40: =SUM(D40:AH40) -> 70 | D40: 70 | E40: 0
...

Sheet TEMPLATE SALES
A1: Concept | E1: Achievement | I1: Budget Campaign
A2: Product | C2: Concept | E2: Target | I2: Budget Awal
A3: 1 | C3: 1 | E3: =Maindata!I3 -> 1000000000 | I3: CAMPAIGN | K3: ADS
C4: 2 | K4: =IFERROR(__xludf.DUMMYFUNCTION("IMPORTRANGE(""https://docs.google.com/spreadsheets/d/1XGHyffJQ7KjI292zt5QVK_1XTfEMh_HDpl_2BHAzd4c/edit?gid=1335890585#gid=1335890585"",""OMG Skincare!H21"") "),2.732E7) -> 27320000
A5: 2 | C5: 1 | E5: Progress
C6: 2 | E6: =SUM(Q16:T249) -> 0 | I6: Budget Terpakai
A7: 3 | C7: 1 | I7: =IFERROR(__xludf.DUMMYFUNCTION("IMPORTRANGE(""https://docs.google.com/spreadsheets/d/1XGHyffJQ7KjI292zt5QVK_1XTfEMh_HDpl_2BHAzd4c/edit?gid=1335890585#gid=1335890585"",""OMG Skincare!H4"")"),6690000.0) -> 6690000 | K7: =IFERROR(__xludf.DUMMYFUNCTION("IMPORTRANGE(""https://docs.google.com/spreadsheets/d/1XGHyffJQ7KjI292zt5QVK_1XTfEMh_HDpl_2BHAzd4c/edit?gid=1335890585#gid=1335890585"",""OMG Skincare!K4"") "),2.432E7) -> 24320000
C8: 2 | E8: Percentage (%)
A9: 4 | C9: 1 | E9: =E6/E3 -> 0 | I9: Sisa Budget
C10: 2 | I10: =I4-I7 -> -6690000 | K10: =K4-K7 -> 3000000
A11: 5 | C11: 1
C12: 2
Q14: Organic Sales | S14: Sales By Ads
A15: Tier | B15: Username Creator | C15: Link Account | D15: No. Whatsapp | E15: Price | F15: Qty Video | G15: Product | H15: Sample Progress | I15: Concept | J15: Link Video 1 | K15: Concept | L15: Link Video 2 | M15: Concept | N15: Link Video 3 | O15: Concept | P15: Link Video 4 | Q15: Video | R15: Livestream | S15: Video | T15: Livestream
A16: =IFERROR(__xludf.DUMMYFUNCTION("QUERY(IMPORTRANGE(""https://docs.google.com/spreadsheets/d/10wdjc5GKQIqHka9D7QGq1b4WkRuVqG0ylA8lw57ns-I/edit?usp=sharing"", ""TEMPLATE SALES!A3:AB1000""), ""SELECT Col1, Col2, Col3, Col4, Col5, Col6, Col11, Col16, Col17, Col18, Col19, Col20, Col21, Col22,"&" Col23, Col24, Col25, Col26, Col27, Col28 WHERE Col12 = 'Approved'"")"),"MEGA") -> MEGA | B16: =IFERROR(__xludf.DUMMYFUNCTION("""COMPUTED_VALUE"""),"A") -> A | C16: =IFERROR(__xludf.DUMMYFUNCTION("""COMPUTED_VALUE"""),"https://www.tiktok.com/@A") -> https://www.tiktok.com/@A | D16: =IFERROR(__xludf.DUMMYFUNCTION("""COMPUTED_VALUE"""),"021") -> 021 | E16: =IFERROR(__xludf.DUMMYFUNCTION("""COMPUTED_VALUE"""),"DF") -> DF | F16: =IFERROR(__xludf.DUMMYFUNCTION("""COMPUTED_VALUE"""),3.0) -> 3 | G16: =IFERROR(__xludf.DUMMYFUNCTION("""COMPUTED_VALUE"""),"OMG OH MY GLOW UV Barrier Sunscreen SPF 50 PA++++ 60 ml") -> OMG OH MY GLOW UV Barrier Sunscreen SPF 50 PA++++ 60 ml | H16: =IFERROR(__xludf.DUMMYFUNCTION("""COMPUTED_VALUE"""),"Sampai") -> Sampai | I16: =IFERROR(__xludf.DUMMYFUNCTION("""COMPUTED_VALUE"""),"Concept 2") -> Concept 2 | J16: =IFERROR(__xludf.DUMMYFUNCTION("""COMPUTED_VALUE"""),"A") -> A | Q16: =IFERROR(__xludf.DUMMYFUNCTION("""COMPUTED_VALUE"""),0.0) -> 0 | R16: =IFERROR(__xludf.DUMMYFUNCTION("""COMPUTED_VALUE"""),0.0) -> 0 | S16: =IFERROR(__xludf.DUMMYFUNCTION("""COMPUTED_VALUE"""),0.0) -> 0 | T16: =IFERROR(__xludf.DUMMYFUNCTION("""COMPUTED_VALUE"""),0.0) -> 0

Sheet LAGI TESTING
A1: Concept | D1: Key Message | E1: Achievement | I1: Budget Campaign
A2: Product | C2: Concept | E2: Target | I2: Budget Awal
A3: 1 | C3: 1 | E3: =Maindata!I3 -> 1000000000 | I3: CAMPAIGN | K3: ADS
C4: 2 | I4: =IFERROR(__xludf.DUMMYFUNCTION("IMPORTRANGE(""https://docs.google.com/spreadsheets/d/1XGHyffJQ7KjI292zt5QVK_1XTfEMh_HDpl_2BHAzd4c/edit?gid=1335890585#gid=1335890585"",""OMG Skincare!H16"") "),7680000.0) -> 7680000 | K4: =IFERROR(__xludf.DUMMYFUNCTION("IMPORTRANGE(""https://docs.google.com/spreadsheets/d/1XGHyffJQ7KjI292zt5QVK_1XTfEMh_HDpl_2BHAzd4c/edit?gid=1335890585#gid=1335890585"",""OMG Skincare!H21"") "),2.732E7) -> 27320000
A5: 2 | C5: 1 | E5: Progress
C6: 2 | E6: =SUM(Q16:T249) -> 80000 | I6: Budget Terpakai
A7: 3 | C7: 1 | I7: =IFERROR(__xludf.DUMMYFUNCTION("IMPORTRANGE(""https://docs.google.com/spreadsheets/d/1XGHyffJQ7KjI292zt5QVK_1XTfEMh_HDpl_2BHAzd4c/edit?gid=1335890585#gid=1335890585"",""OMG Skincare!H4"")"),6690000.0) -> 6690000 | K7: =IFERROR(__xludf.DUMMYFUNCTION("IMPORTRANGE(""https://docs.google.com/spreadsheets/d/1XGHyffJQ7KjI292zt5QVK_1XTfEMh_HDpl_2BHAzd4c/edit?gid=1335890585#gid=1335890585"",""OMG Skincare!K4"") "),2.432E7) -> 24320000
C8: 2 | E8: Percentage (%)
A9: 4 | C9: 1 | E9: =E6/E3 -> 8e-05 | I9: Sisa Budget
C10: 2 | I10: =I4-I7 -> 990000 | K10: =K4-K7 -> 3000000
A11: 5 | C11: 1
C12: 2
Q14: Organic Sales | S14: Sales By Ads
A15: Tier | B15: Username Creator | C15: Link Account | D15: No. Whatsapp | E15: Price | F15: Qty Video | G15: Product | H15: Sample Progress | I15: Concept | J15: Link Video 1 | K15: Concept | L15: Link Video 2 | M15: Concept | N15: Link Video 3 | O15: Concept | P15: Link Video 4 | Q15: Video | R15: Livestream | S15: Video | T15: Livestream
A16: =IFERROR(__xludf.DUMMYFUNCTION("QUERY(IMPORTRANGE(""https://docs.google.com/spreadsheets/d/10wdjc5GKQIqHka9D7QGq1b4WkRuVqG0ylA8lw57ns-I/edit?usp=sharing"", ""LAGI TESTING!A3:AA1000""), ""SELECT Col1, Col2, Col3, Col4, Col5, Col6, Col11, Col15, Col16, Col17, Col18, Col19, Col20, Col21, C"&"ol22, Col23, Col24, Col25, Col26, Col27 WHERE Col12 = 'Approved'"")"),"NANO") -> NANO | B16: =IFERROR(__xludf.DUMMYFUNCTION("""COMPUTED_VALUE"""),"arnilawati") -> arnilawati | C16: =IFERROR(__xludf.DUMMYFUNCTION("""COMPUTED_VALUE"""),"https://www.tiktok.com/@arnilawati") -> https://www.tiktok.com/@arnilawati | D16: =IFERROR(__xludf.DUMMYFUNCTION("""COMPUTED_VALUE"""),8.2188059466E10) -> 82188059466 | E16: =IFERROR(__xludf.DUMMYFUNCTION("""COMPUTED_VALUE"""),150000.0) -> 150000 | F16: =IFERROR(__xludf.DUMMYFUNCTION("""COMPUTED_VALUE"""),2.0) -> 2 | G16: =IFERROR(__xludf.DUMMYFUNCTION("""COMPUTED_VALUE"""),"OMG OH MY GLOW UV Barrier Sunscreen SPF 50 PA++++ 60 ml") -> OMG OH MY GLOW UV Barrier Sunscreen SPF 50 PA++++ 60 ml | H16: =IFERROR(__xludf.DUMMYFUNCTION("""COMPUTED_VALUE"""),"Pengiriman") -> Pengiriman | Q16: =IFERROR(__xludf.DUMMYFUNCTION("""COMPUTED_VALUE"""),20000.0) -> 20000 | R16: =IFERROR(__xludf.DUMMYFUNCTION("""COMPUTED_VALUE"""),20000.0) -> 20000 | S16: =IFERROR(__xludf.DUMMYFUNCTION("""COMPUTED_VALUE"""),20000.0) -> 20000 | T16: =IFERROR(__xludf.DUMMYFUNCTION("""COMPUTED_VALUE"""),20000.0) -> 20000
A17: =IFERROR(__xludf.DUMMYFUNCTION("""COMPUTED_VALUE"""),"MICRO") -> MICRO | B17: =IFERROR(__xludf.DUMMYFUNCTION("""COMPUTED_VALUE"""),"ekbardiary") -> ekbardiary | C17: =IFERROR(__xludf.DUMMYFUNCTION("""COMPUTED_VALUE"""),"https://www.tiktok.com/@ekbardiary") -> https://www.tiktok.com/@ekbardiary | D17: =IFERROR(__xludf.DUMMYFUNCTION("""COMPUTED_VALUE"""),8.2118716575E10) -> 82118716575 | E17: =IFERROR(__xludf.DUMMYFUNCTION("""COMPUTED_VALUE"""),500000.0) -> 500000 | F17: =IFERROR(__xludf.DUMMYFUNCTION("""COMPUTED_VALUE"""),1.0) -> 1 | G17: =IFERROR(__xludf.DUMMYFUNCTION("""COMPUTED_VALUE"""),"[BELI BANYAK, LEBIH MURAH!] OMG Oh My Glow Bright Tone Up UV Barrier Sunscreen SPF 50 PA++ 25 ml") -> [BELI BANYAK, LEBIH MURAH!] OMG Oh My Glow Bright Tone Up UV Barrier Sunscreen SPF 50 PA++ 25 ml | H17: =IFERROR(__xludf.DUMMYFUNCTION("""COMPUTED_VALUE"""),"Pengiriman") -> Pengiriman | I17: =IFERROR(__xludf.DUMMYFUNCTION("""COMPUTED_VALUE"""),"Concept 2") -> Concept 2 | K17: =IFERROR(__xludf.DUMMYFUNCTION("""COMPUTED_VALUE"""),"Concept 2") -> Concept 2 | L17: =IFERROR(__xludf.DUMMYFUNCTION("""COMPUTED_VALUE"""),"https://vt.tiktok.com/ZSa9JWV6x/") -> https://vt.tiktok.com/ZSa9JWV6x/ | M17: =IFERROR(__xludf.DUMMYFUNCTION("""COMPUTED_VALUE"""),"Concept 2") -> Concept 2 | N17: =IFERROR(__xludf.DUMMYFUNCTION("""COMPUTED_VALUE"""),"https://vt.tiktok.com/ZSa9JWV6x/") -> https://vt.tiktok.com/ZSa9JWV6x/ | O17: =IFERROR(__xludf.DUMMYFUNCTION("""COMPUTED_VALUE"""),"Concept 2") -> Concept 2 | P17: =IFERROR(__xludf.DUMMYFUNCTION("""COMPUTED_VALUE"""),"https://vt.tiktok.com/ZSa9JWV6x/") -> https://vt.tiktok.com/ZSa9JWV6x/
A18: =IFERROR(__xludf.DUMMYFUNCTION("""COMPUTED_VALUE"""),"NANO") -> NANO | B18: =IFERROR(__xludf.DUMMYFUNCTION("""COMPUTED_VALUE"""),"queenhannisss") -> queenhannisss | C18: =IFERROR(__xludf.DUMMYFUNCTION("""COMPUTED_VALUE"""),"https://www.tiktok.com/@queenhannisss") -> https://www.tiktok.com/@queenhannisss | D18: =IFERROR(__xludf.DUMMYFUNCTION("""COMPUTED_VALUE"""),8.126685182E9) -> 8126685182 | E18: =IFERROR(__xludf.DUMMYFUNCTION("""COMPUTED_VALUE"""),0.0) -> 0 | F18: =IFERROR(__xludf.DUMMYFUNCTION("""COMPUTED_VALUE"""),4.0) -> 4 | G18: =IFERROR(__xludf.DUMMYFUNCTION("""COMPUTED_VALUE"""),"Brightening & Soothing Toner") -> Brightening & Soothing Toner | H18: =IFERROR(__xludf.DUMMYFUNCTION("""COMPUTED_VALUE"""),"Sampai") -> Sampai | I18: =IFERROR(__xludf.DUMMYFUNCTION("""COMPUTED_VALUE"""),"Concept 2") -> Concept 2 | J18: =IFERROR(__xludf.DUMMYFUNCTION("""COMPUTED_VALUE"""),"https://vt.tiktok.com/ZSa9JWV6x/") -> https://vt.tiktok.com/ZSa9JWV6x/ | K18: =IFERROR(__xludf.DUMMYFUNCTION("""COMPUTED_VALUE"""),"Concept 2") -> Concept 2 | M18: =IFERROR(__xludf.DUMMYFUNCTION("""COMPUTED_VALUE"""),"Concept 2") -> Concept 2 | O18: =IFERROR(__xludf.DUMMYFUNCTION("""COMPUTED_VALUE"""),"Concept 2") -> Concept 2
A19: =IFERROR(__xludf.DUMMYFUNCTION("""COMPUTED_VALUE"""),"NANO") -> NANO | B19: =IFERROR(__xludf.DUMMYFUNCTION("""COMPUTED_VALUE"""),"dreamm.png") -> dreamm.png | C19: =IFERROR(__xludf.DUMMYFUNCTION("""COMPUTED_VALUE"""),"https://www.tiktok.com/@dreamm.png") -> https://www.tiktok.com/@dreamm.png | D19: =IFERROR(__xludf.DUMMYFUNCTION("""COMPUTED_VALUE"""),8.5926503288E10) -> 85926503288 | E19: =IFERROR(__xludf.DUMMYFUNCTION("""COMPUTED_VALUE"""),0.0) -> 0 | F19: =IFERROR(__xludf.DUMMYFUNCTION("""COMPUTED_VALUE"""),1.0) -> 1 | G19: =IFERROR(__xludf.DUMMYFUNCTION("""COMPUTED_VALUE"""),"NEW! OMG Acne & Oil Control UV Barrier Sunscreen SPF50 PA++++ ") -> NEW! OMG Acne & Oil Control UV Barrier Sunscreen SPF50 PA++++ | H19: =IFERROR(__xludf.DUMMYFUNCTION("""COMPUTED_VALUE"""),"Sampai") -> Sampai | I19: =IFERROR(__xludf.DUMMYFUNCTION("""COMPUTED_VALUE""")," Concept 1") -> Concept 1 | K19: =IFERROR(__xludf.DUMMYFUNCTION("""COMPUTED_VALUE""")," Concept 1") -> Concept 1 | M19: =IFERROR(__xludf.DUMMYFUNCTION("""COMPUTED_VALUE""")," Concept 1") -> Concept 1 | O19: =IFERROR(__xludf.DUMMYFUNCTION("""COMPUTED_VALUE""")," Concept 1") -> Concept 1
A20: =IFERROR(__xludf.DUMMYFUNCTION("""COMPUTED_VALUE"""),"MICRO") -> MICRO | B20: =IFERROR(__xludf.DUMMYFUNCTION("""COMPUTED_VALUE"""),"mood.umrah") -> mood.umrah | C20: =IFERROR(__xludf.DUMMYFUNCTION("""COMPUTED_VALUE"""),"https://www.tiktok.com/@mood.umrah") -> https://www.tiktok.com/@mood.umrah | D20: =IFERROR(__xludf.DUMMYFUNCTION("""COMPUTED_VALUE"""),8.5822053758E10) -> 85822053758 | E20: =IFERROR(__xludf.DUMMYFUNCTION("""COMPUTED_VALUE"""),500000.0) -> 500000 | F20: =IFERROR(__xludf.DUMMYFUNCTION("""COMPUTED_VALUE"""),1.0) -> 1 | G20: =IFERROR(__xludf.DUMMYFUNCTION("""COMPUTED_VALUE"""),"NEW! OMG Acne & Oil Control UV Barrier Sunscreen SPF50 PA++++ ") -> NEW! OMG Acne & Oil Control UV Barrier Sunscreen SPF50 PA++++ | H20: =IFERROR(__xludf.DUMMYFUNCTION("""COMPUTED_VALUE"""),"Request") -> Request
A21: =IFERROR(__xludf.DUMMYFUNCTION("""COMPUTED_VALUE"""),"MICRO") -> MICRO | B21: =IFERROR(__xludf.DUMMYFUNCTION("""COMPUTED_VALUE"""),"nris9") -> nris9 | C21: =IFERROR(__xludf.DUMMYFUNCTION("""COMPUTED_VALUE"""),"https://www.tiktok.com/@nris9") -> https://www.tiktok.com/@nris9 | D21: =IFERROR(__xludf.DUMMYFUNCTION("""COMPUTED_VALUE"""),8.7721316159E10) -> 87721316159 | E21: =IFERROR(__xludf.DUMMYFUNCTION("""COMPUTED_VALUE"""),250000.0) -> 250000 | F21: =IFERROR(__xludf.DUMMYFUNCTION("""COMPUTED_VALUE"""),1.0) -> 1 | G21: =IFERROR(__xludf.DUMMYFUNCTION("""COMPUTED_VALUE"""),"Brightening & Soothing Toner") -> Brightening & Soothing Toner | H21: =IFERROR(__xludf.DUMMYFUNCTION("""COMPUTED_VALUE"""),"Sampai") -> Sampai | I21: =IFERROR(__xludf.DUMMYFUNCTION("""COMPUTED_VALUE"""),"Concept 2") -> Concept 2 | J21: =IFERROR(__xludf.DUMMYFUNCTION("""COMPUTED_VALUE"""),"https://vt.tiktok.com/ZSa9bTQGn/") -> https://vt.tiktok.com/ZSa9bTQGn/ | K21: =IFERROR(__xludf.DUMMYFUNCTION("""COMPUTED_VALUE"""),"Concept 2") -> Concept 2 | M21: =IFERROR(__xludf.DUMMYFUNCTION("""COMPUTED_VALUE"""),"Concept 2") -> Concept 2 | O21: =IFERROR(__xludf.DUMMYFUNCTION("""COMPUTED_VALUE"""),"Concept 2") -> Concept 2
A22: =IFERROR(__xludf.DUMMYFUNCTION("""COMPUTED_VALUE"""),"NANO") -> NANO | B22: =IFERROR(__xludf.DUMMYFUNCTION("""COMPUTED_VALUE"""),"beranteminjerawat") -> beranteminjerawat | C22: =IFERROR(__xludf.DUMMYFUNCTION("""COMPUTED_VALUE"""),"https://www.tiktok.com/@beranteminjerawat") -> https://www.tiktok.com/@beranteminjerawat | D22: =IFERROR(__xludf.DUMMYFUNCTION("""COMPUTED_VALUE"""),8.2285558227E10) -> 82285558227 | E22: =IFERROR(__xludf.DUMMYFUNCTION("""COMPUTED_VALUE"""),0.0) -> 0 | F22: =IFERROR(__xludf.DUMMYFUNCTION("""COMPUTED_VALUE"""),1.0) -> 1 | G22: =IFERROR(__xludf.DUMMYFUNCTION("""COMPUTED_VALUE"""),"NEW! OMG Acne & Oil Control UV Barrier Sunscreen SPF50 PA++++ ") -> NEW! OMG Acne & Oil Control UV Barrier Sunscreen SPF50 PA++++ | H22: =IFERROR(__xludf.DUMMYFUNCTION("""COMPUTED_VALUE"""),"Pengiriman") -> Pengiriman
A23: =IFERROR(__xludf.DUMMYFUNCTION("""COMPUTED_VALUE"""),"MICRO") -> MICRO | B23: =IFERROR(__xludf.DUMMYFUNCTION("""COMPUTED_VALUE"""),"lina_chubby94") -> lina_chubby94 | C23: =IFERROR(__xludf.DUMMYFUNCTION("""COMPUTED_VALUE"""),"https://www.tiktok.com/@lina_chubby94") -> https://www.tiktok.com/@lina_chubby94 | D23: =IFERROR(__xludf.DUMMYFUNCTION("""COMPUTED_VALUE"""),8.9626315137E10) -> 89626315137 | E23: =IFERROR(__xludf.DUMMYFUNCTION("""COMPUTED_VALUE"""),0.0) -> 0 | F23: =IFERROR(__xludf.DUMMYFUNCTION("""COMPUTED_VALUE"""),1.0) -> 1 | G23: =IFERROR(__xludf.DUMMYFUNCTION("""COMPUTED_VALUE"""),"[BELI BANYAK, LEBIH MURAH!] OMG Oh My Glow Bright Tone Up UV Barrier Sunscreen SPF 50 PA++ 25 ml") -> [BELI BANYAK, LEBIH MURAH!] OMG Oh My Glow Bright Tone Up UV Barrier Sunscreen SPF 50 PA++ 25 ml | H23: =IFERROR(__xludf.DUMMYFUNCTION("""COMPUTED_VALUE"""),"Sampai") -> Sampai | I23: =IFERROR(__xludf.DUMMYFUNCTION("""COMPUTED_VALUE"""),"Concept 2") -> Concept 2 | J23: =IFERROR(__xludf.DUMMYFUNCTION("""COMPUTED_VALUE"""),"https://vt.tiktok.com/ZSaut274T/") -> https://vt.tiktok.com/ZSaut274T/ | K23: =IFERROR(__xludf.DUMMYFUNCTION("""COMPUTED_VALUE"""),"Concept 2") -> Concept 2 | M23: =IFERROR(__xludf.DUMMYFUNCTION("""COMPUTED_VALUE"""),"Concept 2") -> Concept 2 | O23: =IFERROR(__xludf.DUMMYFUNCTION("""COMPUTED_VALUE"""),"Concept 2") -> Concept 2
A24: =IFERROR(__xludf.DUMMYFUNCTION("""COMPUTED_VALUE"""),"MACRO") -> MACRO | B24: =IFERROR(__xludf.DUMMYFUNCTION("""COMPUTED_VALUE"""),"girltigerr") -> girltigerr | C24: =IFERROR(__xludf.DUMMYFUNCTION("""COMPUTED_VALUE"""),"https://www.tiktok.com/@girltigerr") -> https://www.tiktok.com/@girltigerr | D24: =IFERROR(__xludf.DUMMYFUNCTION("""COMPUTED_VALUE"""),8.2177041906E10) -> 82177041906 | E24: =IFERROR(__xludf.DUMMYFUNCTION("""COMPUTED_VALUE"""),0.0) -> 0 | F24: =IFERROR(__xludf.DUMMYFUNCTION("""COMPUTED_VALUE"""),3.0) -> 3 | G24: =IFERROR(__xludf.DUMMYFUNCTION("""COMPUTED_VALUE"""),"Brightening & Soothing Toner") -> Brightening & Soothing Toner | H24: =IFERROR(__xludf.DUMMYFUNCTION("""COMPUTED_VALUE"""),"Sampai") -> Sampai | I24: =IFERROR(__xludf.DUMMYFUNCTION("""COMPUTED_VALUE"""),"Concept 2") -> Concept 2 | J24: =IFERROR(__xludf.DUMMYFUNCTION("""COMPUTED_VALUE"""),"https://vt.tiktok.com/ZSauTYh5E/") -> https://vt.tiktok.com/ZSauTYh5E/ | K24: =IFERROR(__xludf.DUMMYFUNCTION("""COMPUTED_VALUE"""),"Concept 2") -> Concept 2 | M24: =IFERROR(__xludf.DUMMYFUNCTION("""COMPUTED_VALUE"""),"Concept 2") -> Concept 2 | O24: =IFERROR(__xludf.DUMMYFUNCTION("""COMPUTED_VALUE"""),"Concept 2") -> Concept 2
A25: =IFERROR(__xludf.DUMMYFUNCTION("""COMPUTED_VALUE"""),"MICRO") -> MICRO | B25: =IFERROR(__xludf.DUMMYFUNCTION("""COMPUTED_VALUE"""),"naomiifarsya") -> naomiifarsya | C25: =IFERROR(__xludf.DUMMYFUNCTION("""COMPUTED_VALUE"""),"https://www.tiktok.com/@naomiifarsya") -> https://www.tiktok.com/@naomiifarsya | D25: =IFERROR(__xludf.DUMMYFUNCTION("""COMPUTED_VALUE"""),8.9539258699E11) -> 895392586990 | E25: =IFERROR(__xludf.DUMMYFUNCTION("""COMPUTED_VALUE"""),0.0) -> 0 | G25: =IFERROR(__xludf.DUMMYFUNCTION("""COMPUTED_VALUE"""),"OMG OH MY GLOW UV Barrier Sunscreen SPF 50 PA++++ 60 ml") -> OMG OH MY GLOW UV Barrier Sunscreen SPF 50 PA++++ 60 ml | H25: =IFERROR(__xludf.DUMMYFUNCTION("""COMPUTED_VALUE"""),"Pengiriman") -> Pengiriman
A26: =IFERROR(__xludf.DUMMYFUNCTION("""COMPUTED_VALUE"""),"MICRO") -> MICRO | B26: =IFERROR(__xludf.DUMMYFUNCTION("""COMPUTED_VALUE"""),"thnlykai") -> thnlykai | C26: =IFERROR(__xludf.DUMMYFUNCTION("""COMPUTED_VALUE"""),"https://www.tiktok.com/@thnlykai") -> https://www.tiktok.com/@thnlykai | D26: =IFERROR(__xludf.DUMMYFUNCTION("""COMPUTED_VALUE"""),8.98613759E9) -> 8986137590 | E26: =IFERROR(__xludf.DUMMYFUNCTION("""COMPUTED_VALUE"""),150000.0) -> 150000 | F26: =IFERROR(__xludf.DUMMYFUNCTION("""COMPUTED_VALUE"""),2.0) -> 2 | G26: =IFERROR(__xludf.DUMMYFUNCTION("""COMPUTED_VALUE"""),"OMG OH MY GLOW UV Barrier Sunscreen SPF 50 PA++++ 60 ml") -> OMG OH MY GLOW UV Barrier Sunscreen SPF 50 PA++++ 60 ml
A27: =IFERROR(__xludf.DUMMYFUNCTION("""COMPUTED_VALUE"""),"MACRO") -> MACRO | B27: =IFERROR(__xludf.DUMMYFUNCTION("""COMPUTED_VALUE"""),"putri.antris") -> putri.antris | C27: =IFERROR(__xludf.DUMMYFUNCTION("""COMPUTED_VALUE"""),"https://www.tiktok.com/@putri.antris") -> https://www.tiktok.com/@putri.antris | D27: =IFERROR(__xludf.DUMMYFUNCTION("""COMPUTED_VALUE"""),8.978216006E9) -> 8978216006 | E27: =IFERROR(__xludf.DUMMYFUNCTION("""COMPUTED_VALUE"""),0.0) -> 0 | F27: =IFERROR(__xludf.DUMMYFUNCTION("""COMPUTED_VALUE"""),3.0) -> 3 | G27: =IFERROR(__xludf.DUMMYFUNCTION("""COMPUTED_VALUE"""),"OMG OH MY GLOW UV Barrier Sunscreen SPF 50 PA++++ 60 ml") -> OMG OH MY GLOW UV Barrier Sunscreen SPF 50 PA++++ 60 ml
A28: =IFERROR(__xludf.DUMMYFUNCTION("""COMPUTED_VALUE"""),"MICRO") -> MICRO | B28: =IFERROR(__xludf.DUMMYFUNCTION("""COMPUTED_VALUE"""),"ferenaceta") -> ferenaceta | C28: =IFERROR(__xludf.DUMMYFUNCTION("""COMPUTED_VALUE"""),"https://www.tiktok.com/@ferenaceta") -> https://www.tiktok.com/@ferenaceta | D28: =IFERROR(__xludf.DUMMYFUNCTION("""COMPUTED_VALUE"""),8.95705700911E11) -> 895705700911 | E28: =IFERROR(__xludf.DUMMYFUNCTION("""COMPUTED_VALUE"""),100000.0) -> 100000 | F28: =IFERROR(__xludf.DUMMYFUNCTION("""COMPUTED_VALUE"""),1.0) -> 1 | G28: =IFERROR(__xludf.DUMMYFUNCTION("""COMPUTED_VALUE"""),"OMG OH MY GLOW UV Barrier Sunscreen SPF 50 PA++++ 60 ml") -> OMG OH MY GLOW UV Barrier Sunscreen SPF 50 PA++++ 60 ml
A29: =IFERROR(__xludf.DUMMYFUNCTION("""COMPUTED_VALUE"""),"NANO") -> NANO | B29: =IFERROR(__xludf.DUMMYFUNCTION("""COMPUTED_VALUE"""),"melisadyp") -> melisadyp | C29: =IFERROR(__xludf.DUMMYFUNCTION("""COMPUTED_VALUE"""),"https://www.tiktok.com/@melisadyp") -> https://www.tiktok.com/@melisadyp | D29: =IFERROR(__xludf.DUMMYFUNCTION("""COMPUTED_VALUE"""),8.5174215253E10) -> 85174215253 | E29: =IFERROR(__xludf.DUMMYFUNCTION("""COMPUTED_VALUE"""),0.0) -> 0 | F29: =IFERROR(__xludf.DUMMYFUNCTION("""COMPUTED_VALUE"""),1.0) -> 1 | G29: =IFERROR(__xludf.DUMMYFUNCTION("""COMPUTED_VALUE"""),"OMG OH MY GLOW UV Barrier Sunscreen SPF 50 PA++++ 60 ml") -> OMG OH MY GLOW UV Barrier Sunscreen SPF 50 PA++++ 60 ml
A30: =IFERROR(__xludf.DUMMYFUNCTION("""COMPUTED_VALUE"""),"NANO") -> NANO | B30: =IFERROR(__xludf.DUMMYFUNCTION("""COMPUTED_VALUE"""),"vernikaariani") -> vernikaariani | C30: =IFERROR(__xludf.DUMMYFUNCTION("""COMPUTED_VALUE"""),"https://www.tiktok.com/@vernikaariani") -> https://www.tiktok.com/@vernikaariani | D30: =IFERROR(__xludf.DUMMYFUNCTION("""COMPUTED_VALUE"""),8.5326728022E10) -> 85326728022 | E30: =IFERROR(__xludf.DUMMYFUNCTION("""COMPUTED_VALUE"""),0.0) -> 0 | F30: =IFERROR(__xludf.DUMMYFUNCTION("""COMPUTED_VALUE"""),3.0) -> 3 | G30: =IFERROR(__xludf.DUMMYFUNCTION("""COMPUTED_VALUE"""),"OMG OH MY GLOW UV Barrier Sunscreen SPF 50 PA++++ 60 ml") -> OMG OH MY GLOW UV Barrier Sunscreen SPF 50 PA++++ 60 ml
A31: =IFERROR(__xludf.DUMMYFUNCTION("""COMPUTED_VALUE"""),"MICRO") -> MICRO | B31: =IFERROR(__xludf.DUMMYFUNCTION("""COMPUTED_VALUE"""),"thya_pookie") -> thya_pookie | C31: =IFERROR(__xludf.DUMMYFUNCTION("""COMPUTED_VALUE"""),"https://www.tiktok.com/@thya_pookie") -> https://www.tiktok.com/@thya_pookie | D31: =IFERROR(__xludf.DUMMYFUNCTION("""COMPUTED_VALUE"""),8.5842486796E10) -> 85842486796 | E31: =IFERROR(__xludf.DUMMYFUNCTION("""COMPUTED_VALUE"""),100000.0) -> 100000 | F31: =IFERROR(__xludf.DUMMYFUNCTION("""COMPUTED_VALUE"""),1.0) -> 1 | G31: =IFERROR(__xludf.DUMMYFUNCTION("""COMPUTED_VALUE"""),"OMG OH MY GLOW UV Barrier Sunscreen SPF 50 PA++++ 60 ml") -> OMG OH MY GLOW UV Barrier Sunscreen SPF 50 PA++++ 60 ml
A32: =IFERROR(__xludf.DUMMYFUNCTION("""COMPUTED_VALUE"""),"NANO") -> NANO | B32: =IFERROR(__xludf.DUMMYFUNCTION("""COMPUTED_VALUE"""),"randomtrn") -> randomtrn | C32: =IFERROR(__xludf.DUMMYFUNCTION("""COMPUTED_VALUE"""),"https://www.tiktok.com/@randomtrn") -> https://www.tiktok.com/@randomtrn | D32: =IFERROR(__xludf.DUMMYFUNCTION("""COMPUTED_VALUE"""),8.572229105E10) -> 85722291050 | E32: =IFERROR(__xludf.DUMMYFUNCTION("""COMPUTED_VALUE"""),0.0) -> 0 | F32: =IFERROR(__xludf.DUMMYFUNCTION("""COMPUTED_VALUE"""),2.0) -> 2 | G32: =IFERROR(__xludf.DUMMYFUNCTION("""COMPUTED_VALUE"""),"OMG OH MY GLOW UV Barrier Sunscreen SPF 50 PA++++ 60 ml") -> OMG OH MY GLOW UV Barrier Sunscreen SPF 50 PA++++ 60 ml
A33: =IFERROR(__xludf.DUMMYFUNCTION("""COMPUTED_VALUE"""),"NANO") -> NANO | B33: =IFERROR(__xludf.DUMMYFUNCTION("""COMPUTED_VALUE"""),"sinanr18") -> sinanr18 | C33: =IFERROR(__xludf.DUMMYFUNCTION("""COMPUTED_VALUE"""),"https://www.tiktok.com/@sinanr18") -> https://www.tiktok.com/@sinanr18 | D33: =IFERROR(__xludf.DUMMYFUNCTION("""COMPUTED_VALUE"""),8.9670305045E10) -> 89670305045 | E33: =IFERROR(__xludf.DUMMYFUNCTION("""COMPUTED_VALUE"""),0.0) -> 0 | F33: =IFERROR(__xludf.DUMMYFUNCTION("""COMPUTED_VALUE"""),1.0) -> 1 | G33: =IFERROR(__xludf.DUMMYFUNCTION("""COMPUTED_VALUE"""),"OMG OH MY GLOW UV Barrier Sunscreen SPF 50 PA++++ 60 ml") -> OMG OH MY GLOW UV Barrier Sunscreen SPF 50 PA++++ 60 ml
A34: =IFERROR(__xludf.DUMMYFUNCTION("""COMPUTED_VALUE"""),"NANO") -> NANO | B34: =IFERROR(__xludf.DUMMYFUNCTION("""COMPUTED_VALUE"""),"indysabillah") -> indysabillah | C34: =IFERROR(__xludf.DUMMYFUNCTION("""COMPUTED_VALUE"""),"https://www.tiktok.com/@indysabillah") -> https://www.tiktok.com/@indysabillah | D34: =IFERROR(__xludf.DUMMYFUNCTION("""COMPUTED_VALUE"""),8.1242092003E10) -> 81242092003 | E34: =IFERROR(__xludf.DUMMYFUNCTION("""COMPUTED_VALUE"""),0.0) -> 0 | F34: =IFERROR(__xludf.DUMMYFUNCTION("""COMPUTED_VALUE"""),1.0) -> 1 | G34: =IFERROR(__xludf.DUMMYFUNCTION("""COMPUTED_VALUE"""),"OMG OH MY GLOW UV Barrier Sunscreen SPF 50 PA++++ 60 ml") -> OMG OH MY GLOW UV Barrier Sunscreen SPF 50 PA++++ 60 ml
A35: =IFERROR(__xludf.DUMMYFUNCTION("""COMPUTED_VALUE"""),"NANO") -> NANO | B35: =IFERROR(__xludf.DUMMYFUNCTION("""COMPUTED_VALUE"""),"pildaindah") -> pildaindah | C35: =IFERROR(__xludf.DUMMYFUNCTION("""COMPUTED_VALUE"""),"https://www.tiktok.com/@pildaindah") -> https://www.tiktok.com/@pildaindah | D35: =IFERROR(__xludf.DUMMYFUNCTION("""COMPUTED_VALUE"""),8.2297147196E10) -> 82297147196 | E35: =IFERROR(__xludf.DUMMYFUNCTION("""COMPUTED_VALUE"""),0.0) -> 0 | F35: =IFERROR(__xludf.DUMMYFUNCTION("""COMPUTED_VALUE"""),1.0) -> 1 | G35: =IFERROR(__xludf.DUMMYFUNCTION("""COMPUTED_VALUE"""),"OMG OH MY GLOW UV Barrier Sunscreen SPF 50 PA++++ 60 ml") -> OMG OH MY GLOW UV Barrier Sunscreen SPF 50 PA++++ 60 ml
A36: =IFERROR(__xludf.DUMMYFUNCTION("""COMPUTED_VALUE"""),"NANO") -> NANO | B36: =IFERROR(__xludf.DUMMYFUNCTION("""COMPUTED_VALUE"""),"ceisyaandr") -> ceisyaandr | C36: =IFERROR(__xludf.DUMMYFUNCTION("""COMPUTED_VALUE"""),"https://www.tiktok.com/@ceisyaandr") -> https://www.tiktok.com/@ceisyaandr | D36: =IFERROR(__xludf.DUMMYFUNCTION("""COMPUTED_VALUE"""),8.986957804E9) -> 8986957804 | E36: =IFERROR(__xludf.DUMMYFUNCTION("""COMPUTED_VALUE"""),0.0) -> 0 | F36: =IFERROR(__xludf.DUMMYFUNCTION("""COMPUTED_VALUE"""),3.0) -> 3 | G36: =IFERROR(__xludf.DUMMYFUNCTION("""COMPUTED_VALUE"""),"OMG OH MY GLOW UV Barrier Sunscreen SPF 50 PA++++ 60 ml") -> OMG OH MY GLOW UV Barrier Sunscreen SPF 50 PA++++ 60 ml
A37: =IFERROR(__xludf.DUMMYFUNCTION("""COMPUTED_VALUE"""),"MICRO") -> MICRO | B37: =IFERROR(__xludf.DUMMYFUNCTION("""COMPUTED_VALUE"""),"claudya.dona") -> claudya.dona | C37: =IFERROR(__xludf.DUMMYFUNCTION("""COMPUTED_VALUE"""),"https://www.tiktok.com/@claudya.dona") -> https://www.tiktok.com/@claudya.dona | D37: =IFERROR(__xludf.DUMMYFUNCTION("""COMPUTED_VALUE"""),8.95386273909E11) -> 895386273909 | E37: =IFERROR(__xludf.DUMMYFUNCTION("""COMPUTED_VALUE"""),900000.0) -> 900000 | F37: =IFERROR(__xludf.DUMMYFUNCTION("""COMPUTED_VALUE"""),1.0) -> 1 | G37: =IFERROR(__xludf.DUMMYFUNCTION("""COMPUTED_VALUE"""),"OMG OH MY GLOW UV Barrier Sunscreen SPF 50 PA++++ 60 ml") -> OMG OH MY GLOW UV Barrier Sunscreen SPF 50 PA++++ 60 ml
A38: =IFERROR(__xludf.DUMMYFUNCTION("""COMPUTED_VALUE"""),"MICRO") -> MICRO | B38: =IFERROR(__xludf.DUMMYFUNCTION("""COMPUTED_VALUE"""),"mayang_skincare") -> mayang_skincare | C38: =IFERROR(__xludf.DUMMYFUNCTION("""COMPUTED_VALUE"""),"https://www.tiktok.com/@mayang_skincare") -> https://www.tiktok.com/@mayang_skincare | D38: =IFERROR(__xludf.DUMMYFUNCTION("""COMPUTED_VALUE"""),8.95635947123E11) -> 895635947123 | E38: =IFERROR(__xludf.DUMMYFUNCTION("""COMPUTED_VALUE"""),0.0) -> 0 | F38: =IFERROR(__xludf.DUMMYFUNCTION("""COMPUTED_VALUE"""),2.0) -> 2
A39: =IFERROR(__xludf.DUMMYFUNCTION("""COMPUTED_VALUE"""),"NANO") -> NANO | B39: =IFERROR(__xludf.DUMMYFUNCTION("""COMPUTED_VALUE"""),"shavirapuspitacitra") -> shavirapuspitacitra | C39: =IFERROR(__xludf.DUMMYFUNCTION("""COMPUTED_VALUE"""),"https://www.tiktok.com/@shavirapuspitacitra") -> https://www.tiktok.com/@shavirapuspitacitra | D39: =IFERROR(__xludf.DUMMYFUNCTION("""COMPUTED_VALUE"""),8.7768647289E10) -> 87768647289 | E39: =IFERROR(__xludf.DUMMYFUNCTION("""COMPUTED_VALUE"""),250000.0) -> 250000 | F39: =IFERROR(__xludf.DUMMYFUNCTION("""COMPUTED_VALUE"""),1.0) -> 1
A40: =IFERROR(__xludf.DUMMYFUNCTION("""COMPUTED_VALUE"""),"MICRO") -> MICRO | B40: =IFERROR(__xludf.DUMMYFUNCTION("""COMPUTED_VALUE"""),"rysa_mon") -> rysa_mon | C40: =IFERROR(__xludf.DUMMYFUNCTION("""COMPUTED_VALUE"""),"https://www.tiktok.com/@rysa_mon") -> https://www.tiktok.com/@rysa_mon | D40: =IFERROR(__xludf.DUMMYFUNCTION("""COMPUTED_VALUE"""),8.223288345E10) -> 82232883450 | E40: =IFERROR(__xludf.DUMMYFUNCTION("""COMPUTED_VALUE"""),0.0) -> 0 | F40: =IFERROR(__xludf.DUMMYFUNCTION("""COMPUTED_VALUE"""),3.0) -> 3
A41: =IFERROR(__xludf.DUMMYFUNCTION("""COMPUTED_VALUE"""),"MICRO") -> MICRO | B41: =IFERROR(__xludf.DUMMYFUNCTION("""COMPUTED_VALUE"""),"azahrahf") -> azahrahf | C41: =IFERROR(__xludf.DUMMYFUNCTION("""COMPUTED_VALUE"""),"https://www.tiktok.com/@azahrahf") -> https://www.tiktok.com/@azahrahf | D41: =IFERROR(__xludf.DUMMYFUNCTION("""COMPUTED_VALUE"""),8.512122429E10) -> 85121224290 | E41: =IFERROR(__xludf.DUMMYFUNCTION("""COMPUTED_VALUE"""),1100000.0) -> 1100000 | F41: =IFERROR(__xludf.DUMMYFUNCTION("""COMPUTED_VALUE"""),1.0) -> 1
...

Sheet TEMPLATE AWARENESS
A1: Concept | E1: Achievement | I1: Budget Campaign
A2: Product | C2: Concept | E2: Target Creator | F2: Target Video | G2: Target Views | I2: Budget Awal
A3: 1 | C3: 1 | E3: MANUAL | F3: MANUAL | G3: MANUAL | I3: CAMPAIGN | K3: ADS
C4: 2 | I4: =IFERROR(__xludf.DUMMYFUNCTION("IMPORTRANGE(""https://docs.google.com/spreadsheets/d/1XGHyffJQ7KjI292zt5QVK_1XTfEMh_HDpl_2BHAzd4c/edit?gid=1335890585#gid=1335890585"",""OMG Skincare!H16"") "),7680000.0) -> 7680000 | K4: =IFERROR(__xludf.DUMMYFUNCTION("IMPORTRANGE(""https://docs.google.com/spreadsheets/d/1XGHyffJQ7KjI292zt5QVK_1XTfEMh_HDpl_2BHAzd4c/edit?gid=1335890585#gid=1335890585"",""OMG Skincare!H21"") "),2.732E7) -> 27320000
A5: 2 | C5: 1 | E5: Total Creator | F5: Total Video | G5: Total Views
C6: 2 | E6: =SUM(B15:B1011) -> 0 | F6: =COUNTA(I15:L100) -> 0 | I6: Budget Terpakai
A7: 3 | C7: 1 | I7: =IFERROR(__xludf.DUMMYFUNCTION("IMPORTRANGE(""https://docs.google.com/spreadsheets/d/1XGHyffJQ7KjI292zt5QVK_1XTfEMh_HDpl_2BHAzd4c/edit?gid=1335890585#gid=1335890585"",""OMG Skincare!H4"")"),6690000.0) -> 6690000 | K7: =IFERROR(__xludf.DUMMYFUNCTION("IMPORTRANGE(""https://docs.google.com/spreadsheets/d/1XGHyffJQ7KjI292zt5QVK_1XTfEMh_HDpl_2BHAzd4c/edit?gid=1335890585#gid=1335890585"",""OMG Skincare!K4"") "),2.432E7) -> 24320000
C8: 2 | E8: Percentage (%)
A9: 4 | C9: 1 | I9: Sisa Budget
C10: 2 | I10: =I4-I7 -> 990000 | K10: =K4-K7 -> 3000000
A11: 5 | C11: 1
C12: 2
A14: Tier | B14: Username Creator | C14: Link Account | D14: No. Whatsapp | E14: Price | F14: Qty Video | G14: Product | H14: Sample Progress | I14: Link Video 1 | J14: Link Video 2 | K14: Link Video 3 | L14: Link Video 4 | M14: Notes

Sheet OMG SKINCARE
A1: Concept | E1: Achievement | J1: Budget Campaign
A2: Product | C2: Concept | E2: Target | J2: Budget Awal
A3: 1 | C3: 1 | E3: =Maindata!I3 -> 1000000000 | J3: CAMPAIGN | L3: ADS
C4: 2 | J4: =IFERROR(__xludf.DUMMYFUNCTION("IMPORTRANGE(""https://docs.google.com/spreadsheets/d/1XGHyffJQ7KjI292zt5QVK_1XTfEMh_HDpl_2BHAzd4c/edit?gid=1335890585#gid=1335890585"",""OMG Skincare!H16"") "),7680000.0) -> 7680000 | L4: =IFERROR(__xludf.DUMMYFUNCTION("IMPORTRANGE(""https://docs.google.com/spreadsheets/d/1XGHyffJQ7KjI292zt5QVK_1XTfEMh_HDpl_2BHAzd4c/edit?gid=1335890585#gid=1335890585"",""OMG Skincare!H21"") "),2.732E7) -> 27320000
A5: 2 | C5: 1 | E5: Progress
C6: 2 | E6: =SUM(R17:U250) -> 7.7032641e+08 | J6: Budget Terpakai
A7: 3 | C7: 1 | J7: =IFERROR(__xludf.DUMMYFUNCTION("IMPORTRANGE(""https://docs.google.com/spreadsheets/d/1XGHyffJQ7KjI292zt5QVK_1XTfEMh_HDpl_2BHAzd4c/edit?gid=1335890585#gid=1335890585"",""OMG Skincare!H4"")"),6690000.0) -> 6690000 | L7: =IFERROR(__xludf.DUMMYFUNCTION("IMPORTRANGE(""https://docs.google.com/spreadsheets/d/1XGHyffJQ7KjI292zt5QVK_1XTfEMh_HDpl_2BHAzd4c/edit?gid=1335890585#gid=1335890585"",""OMG Skincare!K4"") "),2.432E7) -> 24320000
C8: 2 | E8: Percentage (%)
A9: 4 | C9: 1 | E9: =E6/E3 -> 0.77032641 | J9: Sisa Budget
C10: 2 | J10: =J4-J7 -> 990000 | L10: =L4-L7 -> 3000000
A11: 5 | C11: 1
C12: 2
R15: Organic Sales | T15: Sales By Ads
A16: Tier | B16: Username Creator | C16: Link Account | D16: No. Whatsapp | E16: Price | F16: Qty Video | G16: GMV | H16: Product | I16: Sample Progress | J16: Concept | K16: Link Video 1 | L16: Concept | M16: Link Video 2 | N16: Concept | O16: Link Video 3 | P16: Concept | Q16: Link Video 4 | R16: Video | S16: Livestream | T16: Video | U16: Livestream
